<?xml version="1.0"?>
<robot name="mx64">
    <ros2_control name="mx64" type="system">
        <hardware>
            <plugin>dynamixel_hardware/DynamixelHardware</plugin>
            <param name="usb_port">/dev/ttyUSB0</param>
            <param name="baud_rate">57600</param>
        </hardware>

        <joint name="joint1">
            <param name="id">1</param>
            <command_interface name="position"/>
            <command_interface name="velocity"/>
            <state_interface name="position"/>
            <state_interface name="velocity"/>
        </joint>
    </ros2_control>

    
    <link name="mx64_base">
        <origin rpy="0 0 0" xyz="0 0 0"/>
    </link>
    <link name="mx64_end">
        <origin rpy="0 0 0" xyz="0 0 0.05"/>
    </link>
    <joint name="joint1" type="revolute">
        <parent link="mx64_base"/>
        <child link="mx64_end"/>
        <origin rpy="0 0 0" xyz="0 0 0.05"/>
        <axis xyz="0 0 1"/>
        <limit effort="50.0" lower="-6.283185307179586" upper="6.283185307179586" velocity="3.14"/>
    </joint>
</robot>